Unable to find image 'sadigngr/test_lib:latest' locally
latest: Pulling from sadigngr/test_lib
7ad3271a525f: Already exists
8031108f3cda: Already exists
1d281e50d3e4: Already exists
447713e77b4f: Already exists
6a5d3adec565: Already exists
80dfafe3215b: Already exists
f5e20e850d9d: Already exists
de4b79d04cf2: Already exists
3c517a5c7342: Already exists
45ba7927522c: Already exists
345f190b0678: Already exists
Digest: sha256:987a78bbcf45246336487a42cf341a4415c287bdc0d48a1c7139c50da1b235e9
Status: Downloaded newer image for sadigngr/test_lib:latest
/usr/local/lib/python3.12/site-packages/sklearn/preprocessing/_data.py:2785: UserWarning: n_quantiles (1000) is greater than the total number of samples (50). n_quantiles is set to n_samples.
  warnings.warn(
